Workbook

Sheet Checks
A1: Checks
A3: # | B3: Check | C3: Value A | D3: Value B | E3: Result
A4: 1 | B4: Opening trial balance sums to zero | C4: =Opening_TB!C14 -> 0 | D4: =0 -> 0 | E4: =IF(ABS(C4-D4)<0.5,"PASS","FAIL") -> PASS
A5: 2 | B5: Trial balance: total debits = total credits | C5: =Trial_Balance!I39 -> 26817342 | D5: =Trial_Balance!J39 -> 26817342 | E5: =IF(ABS(C5-D5)<0.5,"PASS","FAIL") -> PASS
A6: 3 | B6: Journals balance | C6: =Journals!E58 -> 6686888 | D6: =Journals!F58 -> 6686888 | E6: =IF(ABS(C6-D6)<0.5,"PASS","FAIL") -> PASS
A7: 4 | B7: Statement of financial position balances | C7: =SoFP!C17 -> 5983454 | D7: =SoFP!C36 -> 5983454 | E7: =IF(ABS(C7-D7)<0.5,"PASS","FAIL") -> PASS
A8: 5 | B8: Cash flow closing cash = bank in trial balance | C8: =SoCF!C34 -> 1143454 | D8: =SUMIFS(Trial_Balance!$H$5:$H$38,Trial_Balance!$A$5:$A$38,Settings!$B$6) -> 1143454 | E8: =IF(ABS(C8-D8)<0.5,"PASS","FAIL") -> PASS
A9: 6 | B9: Cash flow closing cash = cash book running balance | C9: =SoCF!C34 -> 1143454 | D9: =Cash_Book!$I$115 -> 1143454 | E9: =IF(ABS(C9-D9)<0.5,"PASS","FAIL") -> PASS
A10: 7 | B10: Receivables by customer = receivables control account | C10: =Notes!$B$86 -> 1150000 | D10: =SUMIFS(Trial_Balance!$H$5:$H$38,Trial_Balance!$A$5:$A$38,Settings!$B$7) -> 1150000 | E10: =IF(ABS(C10-D10)<0.5,"PASS","FAIL") -> PASS
A11: 8 | B11: Payables by supplier = payables control account | C11: =Notes!$B$105 -> 500000 | D11: =-SUMIFS(Trial_Balance!$H$5:$H$38,Trial_Balance!$A$5:$A$38,Settings!$B$8) -> 500000 | E11: =IF(ABS(C11-D11)<0.5,"PASS","FAIL") -> PASS
A12: 9 | B12: Fixed asset register carrying amount = PPE in statements | C12: =Fixed_Assets!K9 -> 3340000 | D12: =SoFP!C8 -> 3340000 | E12: =IF(ABS(C12-D12)<0.5,"PASS","FAIL") -> PASS
A13: 10 | B13: PPE note = statement of financial position | C13: =Notes!$B$78 -> 3340000 | D13: =SoFP!C8 -> 3340000 | E13: =IF(ABS(C13-D13)<0.5,"PASS","FAIL") -> PASS
A14: 11 | B14: Fixed asset register opening depreciation = opening trial balance | C14: =Fixed_Assets!G9 -> 600000 | D14: =-SUMIFS(Trial_Balance!$E$5:$E$38,Trial_Balance!$A$5:$A$38,1510) -> 600000 | E14: =IF(ABS(C14-D14)<0.5,"PASS","FAIL") -> PASS
A15: 12 | B15: Loan balance per trial balance = loan schedule | C15: =-SUMIFS(Trial_Balance!$H$5:$H$38,Trial_Balance!$A$5:$A$38,2500) -> 1800000 | D15: =Loan_Schedule!$L$11 -> 1800000 | E15: =IF(ABS(C15-D15)<0.5,"PASS","FAIL") -> PASS
A16: 13 | B16: Loan interest per trial balance = loan schedule | C16: =SUMIFS(Trial_Balance!$H$5:$H$38,Trial_Balance!$A$5:$A$38,8100) -> 264000 | D16: =Loan_Schedule!$J$11 -> 264000 | E16: =IF(ABS(C16-D16)<0.5,"PASS","FAIL") -> PASS
A17: 14 | B17: Net salaries paid = payroll register net pay | C17: =SUMIFS(Cash_Book!$G$5:$G$155,Cash_Book!$E$5:$E$155,2410) -> 3472152 | D17: =Payroll!G17 -> 3472152 | E17: =IF(ABS(C17-D17)<0.5,"PASS","FAIL") -> PASS
A18: 15 | B18: PAYE and RSSB payable = December remittance per payroll register | C18: =Notes!$B$109 -> 143854 | D18: =Payroll!L16 -> 143854 | E18: =IF(ABS(C18-D18)<0.5,"PASS","FAIL") -> PASS
A19: 16 | B19: Current tax in trial balance = tax computation | C19: =SUMIFS(Trial_Balance!$H$5:$H$38,Trial_Balance!$A$5:$A$38,7000) -> 180488 | D19: =Tax_Computation!B16 -> 180488 | E19: =IF(ABS(C19-D19)<0.5,"PASS","FAIL") -> PASS
A20: 17 | B20: Deferred tax liability in trial balance = tax computation | C20: =-SUMIFS(Trial_Balance!$H$5:$H$38,Trial_Balance!$A$5:$A$38,2700) -> 217000 | D20: =Tax_Computation!B22 -> 217000 | E20: =IF(ABS(C20-D20)<0.5,"PASS","FAIL") -> PASS
A21: 18 | B21: Tax expense = 28% x (profit before tax + non-deductible expenses), within rounding | C21: =Notes!$B$61 -> 313488 | D21: =ROUND((SoCI!C17+Tax_Computation!B13)*Settings!$B$5,0) -> 313488 | E21: =IF(ABS(C21-D21)<2,"PASS","FAIL") -> PASS
A22: 19 | B22: Revenue note = income statement | C22: =Notes!$B$19 -> 19550000 | D22: =SoCI!C6 -> 19550000 | E22: =IF(ABS(C22-D22)<0.5,"PASS","FAIL") -> PASS
A23: 20 | B23: Expenses by nature = cost of sales + administrative + selling expenses | C23: =Notes!$B$50 -> 18166400 | D23: =-(SoCI!C7+SoCI!C10+SoCI!C11) -> 18166400 | E23: =IF(ABS(C23-D23)<0.5,"PASS","FAIL") -> PASS
A24: 21 | B24: Three-statement model: actual-year cash = statement of cash flows | C24: =Three_Statement_Model!B71 -> 1143454 | D24: =SoCF!C34 -> 1143454 | E24: =IF(ABS(C24-D24)<0.5,"PASS","FAIL") -> PASS
A25: 22 | B25: Three-statement model balances in every year | C25: =SUMPRODUCT(ABS(Three_Statement_Model!B52:E52)) -> 0 | D25: =0 -> 0 | E25: =IF(ABS(C25-D25)<0.5,"PASS","FAIL") -> PASS
A26: 23 | B26: Every coded line in registers, cash book and journals uses a valid account code | E26: =IF(COUNTIF(Sales_Register!$G$5:$G$65,"INVALID CODE")+COUNTIF(Purchase_Register!$G$5:$G$94,"INVALID CODE")+COUNTIF(Cash_Book!$H$5:$H$155,"INVALID CODE")+COUNTIF(Journals!$G$5:$G$56,"INVALID CODE")=0,"PASS","FAIL") -> PASS
B28: Overall | E28: =IF(COUNTIF(E4:E26,"FAIL")=0,"ALL PASS","REVIEW") -> ALL PASS

Sheet Read_Me
A1: Financial Management Workbook — IFRS for SMEs, Rwanda (extended version)
A2: Author: Anicet Safari, CPA · October 2026 · Fictional company and figures
A4: Purpose
A5: Shows how the simplified cash-book workbook I designed for a small client scales up to accrual accounting, a full set of financial statements under the
A6: IFRS for SMEs Accounting Standard, Rwandan tax and payroll rules, and an integrated three-statement forecast model. It is not the file delivered to the client.
A8: Data flow
A9: Inputs: Settings, COA, Opening_TB, Sales_Register, Purchase_Register, Payroll, Cash_Book, Fixed_Assets, Loan_Schedule, Tax_Computation, Journals
A10: -> Trial_Balance (built by formula from every input sheet) -> SoFP, SoCI, SoCE, SoCF, Notes -> Three_Statement_Model -> Checks
A12: Rwandan rules applied (rates held in Settings so they can be updated)
A13: Corporate income tax 28% · tax depreciation (wear and tear) 50% computers and ICT, 25% other business assets, reducing balance
A14: PAYE monthly bands 0% to RWF 60,000, 10% to 100,000, 20% to 200,000, 30% above · RSSB: pension 6% employee + 6% employer, occupational hazards 2% employer,
A15: maternity 0.3% + 0.3%, CBHI 0.5% of net salary · PAYE and RSSB remitted by the 15th of the following month · quarterly income tax prepayments (30 June, 30 September,
... A22: Colour legend: blue on yellow = input · black = formula · green = link to another sheet

Sheet Company_Info
A1: Corporate information and statement of directors' responsibilities
A4: Company | B4: =Settings!$B$3 -> Example Tech Ltd (fictional)
A5: Legal form | B5: Private limited company incorporated in Rwanda (fictional)
A6: Registered office | B6: Kigali, Rwanda
A7: Principal activity | B7: Software development, IT support and digital skills training
A8: Directors | B8: Director A (Managing Director); Director B
A9: Bankers | B9: A commercial bank in Kigali
A10: Tax status | B10: Registered for corporate income tax and PAYE with RRA; not registered for VAT (2025 turnover below the RWF 20 million threshold)
A13: Statement of directors' responsibilities
A14: Law Nº 007/2021 of 05/02/2021 governing companies requires the directors to keep proper accounting records and to prepare financial statements for each financial year
A15: that give a true and fair view of the financial position and performance of the company. The directors have prepared these financial statements in accordance with the
A16: IFRS for SMEs Accounting Standard. They are responsible for internal controls that prevent and detect fraud and error, for selecting and applying suitable accounting
A17: policies, for making reasonable estimates, and for assessing whether the company can continue as a going concern. The company files its annual return with the Rwanda
A18: Development Board and its tax declarations with the Rwanda Revenue Authority.
A20: Approved by the board of directors and signed on its behalf: ____________________ Director ____________________ Director

Sheet Settings
A1: Settings and Rwandan tax parameters
A3: Company name | B3: Example Tech Ltd (fictional)
A4: Financial year (calendar) | B4: 2025
A5: Corporate income tax rate | B5: 0.28
A6: Bank account code | B6: 1100
A7: Trade receivables control code | B7: 1200
A8: Trade payables control code | B8: 2100
A9: PAYE band 1 upper limit (0%) | B9: 60000
A10: PAYE band 2 upper limit (10%) | B10: 100000
A11: PAYE band 3 upper limit (20%) | B11: 200000
A12: PAYE rate band 2 | B12: 0.1
A13: PAYE rate band 3 | B13: 0.2
A14: PAYE rate above band 3 | B14: 0.3
A15: RSSB pension - employee | B15: 0.06
... A23: Wear and tear - other business assets | B23: 0.25
A25: Sources: Rwanda Revenue Authority income tax guide 2025; PwC Worldwide Tax Summaries (Rwanda). Check rates against current law before use.
A26: All amounts in Rwandan francs (RWF).

Sheet COA
A1: Chart of accounts
A3: Code | B3: Account | C3: Class | D3: Statement line | E3: Nature (expense note)
A4: 1100 | B4: Bank | C4: Asset | D4: Cash and cash equivalents
A5: 1200 | B5: Trade receivables | C5: Asset | D5: Trade and other receivables
A6: 1300 | B6: Prepayments | C6: Asset | D6: Prepayments
A7: 1500 | B7: Property, plant and equipment - cost | C7: Asset | D7: Property, plant and equipment
A8: 1510 | B8: Property, plant and equipment - accumulated depreciation | C8: Asset | D8: Property, plant and equipment
A9: 2100 | B9: Trade payables | C9: Liability | D9: Trade and other payables
A10: 2200 | B10: Accrued expenses | C10: Liability | D10: Trade and other payables
A11: 2300 | B11: Income tax payable | C11: Liability | D11: Current income tax liability
A12: 2400 | B12: PAYE and RSSB contributions payable | C12: Liability | D12: PAYE and social security payable
A13: 2410 | B13: Net salaries payable | C13: Liability | D13: Trade and other payables
A14: 2500 | B14: Bank loan | C14: Liability | D14: Borrowings
A15: 2700 | B15: Deferred tax liability | C15: Liability | D15: Deferred tax liability
... A22: 4300 | B22: Other income | C22: Income | D22: Other income
A23: 5000 | B23: Contractor costs | C23: Expense | D23: Cost of sales | E23: Contractor costs
A24: 5500 | B24: Software subscriptions | C24: Expense | D24: Cost of sales | E24: Software and subscriptions
A25: 5010 | B25: Salaries and wages | C25: Expense | D25: Administrative expenses | E25: Employee benefits
A26: 5020 | B26: Employer RSSB contributions | C26: Expense | D26: Administrative expenses | E26: Employee benefits
A27: 5100 | B27: Office rent | C27: Expense | D27: Administrative expenses | E27: Premises
A28: 5300 | B28: Electricity and water | C28: Expense | D28: Administrative expenses | E28: Premises
A29: 5200 | B29: Internet and communication | C29: Expense | D29: Administrative expenses | E29: Communication
A30: 5400 | B30: Transport | C30: Expense | D30: Administrative expenses | E30: Transport
A31: 5600 | B31: Bank charges | C31: Expense | D31: Administrative expenses | E31: Bank charges
A32: 5800 | B32: Trading licence and fees | C32: Expense | D32: Administrative expenses | E32: Licences and fees
A33: 6100 | B33: Depreciation | C33: Expense | D33: Administrative expenses | E33: Depreciation
A34: 5700 | B34: Marketing | C34: Expense | D34: Selling and marketing expenses | E34: Marketing
A35: 8100 | B35: Interest on bank loan | C35: Expense | D35: Finance costs | E35: Interest
A36: 7000 | B36: Current income tax | C36: Tax | D36: Income tax expense
A37: 7100 | B37: Deferred tax | C37: Tax | D37: Income tax expense

Sheet Opening_TB
A1: Opening trial balance at 1 January
A2: Debit balances positive, credit balances negative; brought forward from the prior year's audited balances (fictional).
A4: Code | B4: Account | C4: Balance (Dr + / Cr −) | E4: Opening balances by party
A5: 1100 | B5: =INDEX(COA!$B$4:$B$37,MATCH(A5,COA!$A$4:$A$37,0)) -> Bank | C5: 1500000 | E5: Party | F5: Type | G5: Balance
A6: 1200 | B6: =INDEX(COA!$B$4:$B$37,MATCH(A6,COA!$A$4:$A$37,0)) -> Trade receivables | C6: 600000 | E6: Client A | F6: Customer | G6: 600000
A7: 1500 | B7: =INDEX(COA!$B$4:$B$37,MATCH(A7,COA!$A$4:$A$37,0)) -> Property, plant and equipment - cost | C7: 1800000 | E7: Contractors | F7: Supplier | G7: 250000
A8: 1510 | B8: =INDEX(COA!$B$4:$B$37,MATCH(A8,COA!$A$4:$A$37,0)) -> Property, plant and equipment - accumulated depreciation | C8: -600000
A9: 2100 | B9: =INDEX(COA!$B$4:$B$37,MATCH(A9,COA!$A$4:$A$37,0)) -> Trade payables | C9: -250000
A10: 2300 | B10: =INDEX(COA!$B$4:$B$37,MATCH(A10,COA!$A$4:$A$37,0)) -> Income tax payable | C10: -180000
A11: 2700 | B11: =INDEX(COA!$B$4:$B$37,MATCH(A11,COA!$A$4:$A$37,0)) -> Deferred tax liability | C11: -84000
A12: 3000 | B12: =INDEX(COA!$B$4:$B$37,MATCH(A12,COA!$A$4:$A$37,0)) -> Share capital | C12: -1000000
A13: 3100 | B13: =INDEX(COA!$B$4:$B$37,MATCH(A13,COA!$A$4:$A$37,0)) -> Retained earnings | C13: -1786000
B14: Total (must be zero) | C14: =SUM(C5:C13) -> 0

Sheet Sales_Register
A1: Sales register (invoices issued)
A2: Revenue is recognised when the service is delivered and invoiced: Dr Trade receivables, Cr Revenue (IFRS for SMEs Section 23).
A4: Date | B4: Invoice | C4: Customer | D4: Description | E4: Revenue code | F4: Amount | G4: Account
A5: 45658 | B5: INV-001 | C5: Client B | D5: IT support - January | E5: 4100 | F5: 550000 | G5: =IF(E5="","",IFERROR(INDEX(COA!$B$4:$B$37,MATCH(E5,COA!$A$4:$A$37,0)),"INVALID CODE")) -> IT support and maintenance
A6: 45663 | B6: INV-101 | C6: Client A | D6: Website build - milestone 1 delivered | E6: 4000 | F6: 1800000 | G6: =IF(E6="","",IFERROR(INDEX(COA!$B$4:$B$37,MATCH(E6,COA!$A$4:$A$37,0)),"INVALID CODE")) -> Software development services
A7: 45689 | B7: INV-002 | C7: Client B | D7: IT support - February | E7: 4100 | F7: 550000 | G7: =IF(E7="","",IFERROR(INDEX(COA!$B$4:$B$37,MATCH(E7,COA!$A$4:$A$37,0)),"INVALID CODE")) -> IT support and maintenance
A8: 45717 | B8: INV-003 | C8: Client B | D8: IT support - March | E8: 4100 | F8: 550000 | G8: =IF(E8="","",IFERROR(INDEX(COA!$B$4:$B$37,MATCH(E8,COA!$A$4:$A$37,0)),"INVALID CODE")) -> IT support and maintenance
A9: 45721 | B9: INV-102 | C9: Client A | D9: Website build - final delivery | E9: 4000 | F9: 1200000 | G9: =IF(E9="","",IFERROR(INDEX(COA!$B$4:$B$37,MATCH(E9,COA!$A$4:$A$37,0)),"INVALID CODE")) -> Software development services
A10: 45748 | B10: INV-004 | C10: Client B | D10: IT support - April | E10: 4100 | F10: 550000 | G10: =IF(E10="","",IFERROR(INDEX(COA!$B$4:$B$37,MATCH(E10,COA!$A$4:$A$37,0)),"INVALID CODE")) -> IT support and maintenance
A11: 45755 | B11: INV-103 | C11: Training participants | D11: Digital skills training - cohort 1 | E11: 4200 | F11: 900000 | G11: =IF(E11="","",IFERROR(INDEX(COA!$B$4:$B$37,MATCH(E11,COA!$A$4:$A$37,0)),"INVALID CODE")) -> Training fees
A12: 45778 | B12: INV-005 | C12: Client B | D12: IT support - May | E12: 4100 | F12: 550000 | G12: =IF(E12="","",IFERROR(INDEX(COA!$B$4:$B$37,MATCH(E12,COA!$A$4:$A$37,0)),"INVALID CODE")) -> IT support and maintenance
A13: 45809 | B13: INV-006 | C13: Client B | D13: IT support - June | E13: 4100 | F13: 550000 | G13: =IF(E13="","",IFERROR(INDEX(COA!$B$4:$B$37,MATCH(E13,COA!$A$4:$A$37,0)),"INVALID CODE")) -> IT support and maintenance
A14: 45817 | B14: INV-104 | C14: Client C | D14: Mobile app - milestone 1 delivered | E14: 4000 | F14: 2500000 | G14: =IF(E14="","",IFERROR(INDEX(COA!$B$4:$B$37,MATCH(E14,COA!$A$4:$A$37,0)),"INVALID CODE")) -> Software development services
A15: 45839 | B15: INV-007 | C15: Client B | D15: IT support - July | E15: 4100 | F15: 550000 | G15: =IF(E15="","",IFERROR(INDEX(COA!$B$4:$B$37,MATCH(E15,COA!$A$4:$A$37,0)),"INVALID CODE")) -> IT support and maintenance
A16: 45870 | B16: INV-008 | C16: Client B | D16: IT support - August | E16: 4100 | F16: 550000 | G16: =IF(E16="","",IFERROR(INDEX(COA!$B$4:$B$37,MATCH(E16,COA!$A$4:$A$37,0)),"INVALID CODE")) -> IT support and maintenance
... A25: 46006 | B25: INV-109 | C25: Client D | D25: Website maintenance - Q4 | E25: 4100 | F25: 600000 | G25: =IF(E25="","",IFERROR(INDEX(COA!$B$4:$B$37,MATCH(E25,COA!$A$4:$A$37,0)),"INVALID CODE")) -> IT support and maintenance
G26: =IF(E26="","",IFERROR(INDEX(COA!$B$4:$B$37,MATCH(E26,COA!$A$4:$A$37,0)),"INVALID CODE"))
G27: =IF(E27="","",IFERROR(INDEX(COA!$B$4:$B$37,MATCH(E27,COA!$A$4:$A$37,0)),"INVALID CODE"))
G28: =IF(E28="","",IFERROR(INDEX(COA!$B$4:$B$37,MATCH(E28,COA!$A$4:$A$37,0)),"INVALID CODE"))
G29: =IF(E29="","",IFERROR(INDEX(COA!$B$4:$B$37,MATCH(E29,COA!$A$4:$A$37,0)),"INVALID CODE"))
G30: =IF(E30="","",IFERROR(INDEX(COA!$B$4:$B$37,MATCH(E30,COA!$A$4:$A$37,0)),"INVALID CODE"))
G31: =IF(E31="","",IFERROR(INDEX(COA!$B$4:$B$37,MATCH(E31,COA!$A$4:$A$37,0)),"INVALID CODE"))
G32: =IF(E32="","",IFERROR(INDEX(COA!$B$4:$B$37,MATCH(E32,COA!$A$4:$A$37,0)),"INVALID CODE"))
G33: =IF(E33="","",IFERROR(INDEX(COA!$B$4:$B$37,MATCH(E33,COA!$A$4:$A$37,0)),"INVALID CODE"))
G34: =IF(E34="","",IFERROR(INDEX(COA!$B$4:$B$37,MATCH(E34,COA!$A$4:$A$37,0)),"INVALID CODE"))
G35: =IF(E35="","",IFERROR(INDEX(COA!$B$4:$B$37,MATCH(E35,COA!$A$4:$A$37,0)),"INVALID CODE"))
G36: =IF(E36="","",IFERROR(INDEX(COA!$B$4:$B$37,MATCH(E36,COA!$A$4:$A$37,0)),"INVALID CODE"))
G37: =IF(E37="","",IFERROR(INDEX(COA!$B$4:$B$37,MATCH(E37,COA!$A$4:$A$37,0)),"INVALID CODE"))
... G65: =IF(E65="","",IFERROR(INDEX(COA!$B$4:$B$37,MATCH(E65,COA!$A$4:$A$37,0)),"INVALID CODE"))

Sheet Purchase_Register
A1: Purchase register (supplier bills received)
A2: Expenses are recognised when the goods or services are received: Dr Expense, Cr Trade payables.
A4: Date | B4: Bill ref | C4: Supplier | D4: Description | E4: Account code | F4: Amount | G4: Account
A5: 45658 | B5: B-R01 | C5: Landlord | D5: Office rent - January | E5: 5100 | F5: 350000 | G5: =IF(E5="","",IFERROR(INDEX(COA!$B$4:$B$37,MATCH(E5,COA!$A$4:$A$37,0)),"INVALID CODE")) -> Office rent
A6: 45677 | B6: B-I01 | C6: Internet provider | D6: Internet - January | E6: 5200 | F6: 60000 | G6: =IF(E6="","",IFERROR(INDEX(COA!$B$4:$B$37,MATCH(E6,COA!$A$4:$A$37,0)),"INVALID CODE")) -> Internet and communication
A7: 45679 | B7: B-E01 | C7: Utility company | D7: Electricity and water - January | E7: 5300 | F7: 80000 | G7: =IF(E7="","",IFERROR(INDEX(COA!$B$4:$B$37,MATCH(E7,COA!$A$4:$A$37,0)),"INVALID CODE")) -> Electricity and water
A8: 45685 | B8: B-C01 | C8: Contractors | D8: Contractor services - January | E8: 5000 | F8: 400000 | G8: =IF(E8="","",IFERROR(INDEX(COA!$B$4:$B$37,MATCH(E8,COA!$A$4:$A$37,0)),"INVALID CODE")) -> Contractor costs
A9: 45689 | B9: B-R02 | C9: Landlord | D9: Office rent - February | E9: 5100 | F9: 350000 | G9: =IF(E9="","",IFERROR(INDEX(COA!$B$4:$B$37,MATCH(E9,COA!$A$4:$A$37,0)),"INVALID CODE")) -> Office rent
A10: 45702 | B10: B-S01 | C10: Software vendor | D10: Annual software subscriptions | E10: 5500 | F10: 120000 | G10: =IF(E10="","",IFERROR(INDEX(COA!$B$4:$B$37,MATCH(E10,COA!$A$4:$A$37,0)),"INVALID CODE")) -> Software subscriptions
A11: 45708 | B11: B-I02 | C11: Internet provider | D11: Internet - February | E11: 5200 | F11: 60000 | G11: =IF(E11="","",IFERROR(INDEX(COA!$B$4:$B$37,MATCH(E11,COA!$A$4:$A$37,0)),"INVALID CODE")) -> Internet and communication
A12: 45710 | B12: B-E02 | C12: Utility company | D12: Electricity and water - February | E12: 5300 | F12: 80000 | G12: =IF(E12="","",IFERROR(INDEX(COA!$B$4:$B$37,MATCH(E12,COA!$A$4:$A$37,0)),"INVALID CODE")) -> Electricity and water
A13: 45716 | B13: B-C02 | C13: Contractors | D13: Contractor services - February | E13: 5000 | F13: 400000 | G13: =IF(E13="","",IFERROR(INDEX(COA!$B$4:$B$37,MATCH(E13,COA!$A$4:$A$37,0)),"INVALID CODE")) -> Contractor costs
A14: 45717 | B14: B-R03 | C14: Landlord | D14: Office rent - March | E14: 5100 | F14: 350000 | G14: =IF(E14="","",IFERROR(INDEX(COA!$B$4:$B$37,MATCH(E14,COA!$A$4:$A$37,0)),"INVALID CODE")) -> Office rent
A15: 45736 | B15: B-I03 | C15: Internet provider | D15: Internet - March | E15: 5200 | F15: 60000 | G15: =IF(E15="","",IFERROR(INDEX(COA!$B$4:$B$37,MATCH(E15,COA!$A$4:$A$37,0)),"INVALID CODE")) -> Internet and communication
A16: 45738 | B16: B-E03 | C16: Utility company | D16: Electricity and water - March | E16: 5300 | F16: 80000 | G16: =IF(E16="","",IFERROR(INDEX(COA!$B$4:$B$37,MATCH(E16,COA!$A$4:$A$37,0)),"INVALID CODE")) -> Electricity and water
... A54: 46019 | B54: B-C12 | C54: Contractors | D54: Contractor services - December | E54: 5000 | F54: 500000 | G54: =IF(E54="","",IFERROR(INDEX(COA!$B$4:$B$37,MATCH(E54,COA!$A$4:$A$37,0)),"INVALID CODE")) -> Contractor costs
G55: =IF(E55="","",IFERROR(INDEX(COA!$B$4:$B$37,MATCH(E55,COA!$A$4:$A$37,0)),"INVALID CODE"))
G56: =IF(E56="","",IFERROR(INDEX(COA!$B$4:$B$37,MATCH(E56,COA!$A$4:$A$37,0)),"INVALID CODE"))
G57: =IF(E57="","",IFERROR(INDEX(COA!$B$4:$B$37,MATCH(E57,COA!$A$4:$A$37,0)),"INVALID CODE"))
G58: =IF(E58="","",IFERROR(INDEX(COA!$B$4:$B$37,MATCH(E58,COA!$A$4:$A$37,0)),"INVALID CODE"))
G59: =IF(E59="","",IFERROR(INDEX(COA!$B$4:$B$37,MATCH(E59,COA!$A$4:$A$37,0)),"INVALID CODE"))
G60: =IF(E60="","",IFERROR(INDEX(COA!$B$4:$B$37,MATCH(E60,COA!$A$4:$A$37,0)),"INVALID CODE"))
G61: =IF(E61="","",IFERROR(INDEX(COA!$B$4:$B$37,MATCH(E61,COA!$A$4:$A$37,0)),"INVALID CODE"))
G62: =IF(E62="","",IFERROR(INDEX(COA!$B$4:$B$37,MATCH(E62,COA!$A$4:$A$37,0)),"INVALID CODE"))
G63: =IF(E63="","",IFERROR(INDEX(COA!$B$4:$B$37,MATCH(E63,COA!$A$4:$A$37,0)),"INVALID CODE"))
G64: =IF(E64="","",IFERROR(INDEX(COA!$B$4:$B$37,MATCH(E64,COA!$A$4:$A$37,0)),"INVALID CODE"))
G65: =IF(E65="","",IFERROR(INDEX(COA!$B$4:$B$37,MATCH(E65,COA!$A$4:$A$37,0)),"INVALID CODE"))
G66: =IF(E66="","",IFERROR(INDEX(COA!$B$4:$B$37,MATCH(E66,COA!$A$4:$A$37,0)),"INVALID CODE"))
... G94: =IF(E94="","",IFERROR(INDEX(COA!$B$4:$B$37,MATCH(E94,COA!$A$4:$A$37,0)),"INVALID CODE"))

Sheet Payroll
A1: Payroll register — Rwanda PAYE and RSSB
A2: One employee (administration and finance officer). Rates from Settings. Deductions and employer contributions are remitted by the 15th of the following month.
A4: Month | B4: Gross salary | C4: PAYE | D4: Pension (employee) | E4: Maternity (employee) | F4: CBHI (employee) | G4: Net pay | H4: Pension (employer) | I4: Occupational hazards (employer) | J4: Maternity (employer) | K4: Employer contributions | L4: Total to remit (RRA / RSSB)
A5: 45658 | B5: 400000 | C5: =ROUND(MAX(0,MIN(B5,Settings!$B$10)-Settings!$B$9)*Settings!$B$12+MAX(0,MIN(B5,Settings!$B$11)-Settings!$B$10)*Settings!$B$13+MAX(0,B5-Settings!$B$11)*Settings!$B$14,0) -> 84000 | D5: =ROUND(B5*Settings!$B$15,0) -> 24000 | E5: =ROUND(B5*Settings!$B$18,0) -> 1200 | F5: =ROUND((B5-C5-D5-E5)*Settings!$B$20,0) -> 1454 | G5: =B5-C5-D5-E5-F5 -> 289346 | H5: =ROUND(B5*Settings!$B$16,0) -> 24000 | I5: =ROUND(B5*Settings!$B$17,0) -> 8000 | J5: =ROUND(B5*Settings!$B$19,0) -> 1200 | K5: =H5+I5+J5 -> 33200 | L5: =C5+D5+E5+F5+K5 -> 143854
A6: 45689 | B6: 400000 | C6: =ROUND(MAX(0,MIN(B6,Settings!$B$10)-Settings!$B$9)*Settings!$B$12+MAX(0,MIN(B6,Settings!$B$11)-Settings!$B$10)*Settings!$B$13+MAX(0,B6-Settings!$B$11)*Settings!$B$14,0) -> 84000 | D6: =ROUND(B6*Settings!$B$15,0) -> 24000 | E6: =ROUND(B6*Settings!$B$18,0) -> 1200 | F6: =ROUND((B6-C6-D6-E6)*Settings!$B$20,0) -> 1454 | G6: =B6-C6-D6-E6-F6 -> 289346 | H6: =ROUND(B6*Settings!$B$16,0) -> 24000 | I6: =ROUND(B6*Settings!$B$17,0) -> 8000 | J6: =ROUND(B6*Settings!$B$19,0) -> 1200 | K6: =H6+I6+J6 -> 33200 | L6: =C6+D6+E6+F6+K6 -> 143854
A7: 45717 | B7: 400000 | C7: =ROUND(MAX(0,MIN(B7,Settings!$B$10)-Settings!$B$9)*Settings!$B$12+MAX(0,MIN(B7,Settings!$B$11)-Settings!$B$10)*Settings!$B$13+MAX(0,B7-Settings!$B$11)*Settings!$B$14,0) -> 84000 | D7: =ROUND(B7*Settings!$B$15,0) -> 24000 | E7: =ROUND(B7*Settings!$B$18,0) -> 1200 | F7: =ROUND((B7-C7-D7-E7)*Settings!$B$20,0) -> 1454 | G7: =B7-C7-D7-E7-F7 -> 289346 | H7: =ROUND(B7*Settings!$B$16,0) -> 24000 | I7: =ROUND(B7*Settings!$B$17,0) -> 8000 | J7: =ROUND(B7*Settings!$B$19,0) -> 1200 | K7: =H7+I7+J7 -> 33200 | L7: =C7+D7+E7+F7+K7 -> 143854
A8: 45748 | B8: 400000 | C8: =ROUND(MAX(0,MIN(B8,Settings!$B$10)-Settings!$B$9)*Settings!$B$12+MAX(0,MIN(B8,Settings!$B$11)-Settings!$B$10)*Settings!$B$13+MAX(0,B8-Settings!$B$11)*Settings!$B$14,0) -> 84000 | D8: =ROUND(B8*Settings!$B$15,0) -> 24000 | E8: =ROUND(B8*Settings!$B$18,0) -> 1200 | F8: =ROUND((B8-C8-D8-E8)*Settings!$B$20,0) -> 1454 | G8: =B8-C8-D8-E8-F8 -> 289346 | H8: =ROUND(B8*Settings!$B$16,0) -> 24000 | I8: =ROUND(B8*Settings!$B$17,0) -> 8000 | J8: =ROUND(B8*Settings!$B$19,0) -> 1200 | K8: =H8+I8+J8 -> 33200 | L8: =C8+D8+E8+F8+K8 -> 143854
A9: 45778 | B9: 400000 | C9: =ROUND(MAX(0,MIN(B9,Settings!$B$10)-Settings!$B$9)*Settings!$B$12+MAX(0,MIN(B9,Settings!$B$11)-Settings!$B$10)*Settings!$B$13+MAX(0,B9-Settings!$B$11)*Settings!$B$14,0) -> 84000 | D9: =ROUND(B9*Settings!$B$15,0) -> 24000 | E9: =ROUND(B9*Settings!$B$18,0) -> 1200 | F9: =ROUND((B9-C9-D9-E9)*Settings!$B$20,0) -> 1454 | G9: =B9-C9-D9-E9-F9 -> 289346 | H9: =ROUND(B9*Settings!$B$16,0) -> 24000 | I9: =ROUND(B9*Settings!$B$17,0) -> 8000 | J9: =ROUND(B9*Settings!$B$19,0) -> 1200 | K9: =H9+I9+J9 -> 33200 | L9: =C9+D9+E9+F9+K9 -> 143854
A10: 45809 | B10: 400000 | C10: =ROUND(MAX(0,MIN(B10,Settings!$B$10)-Settings!$B$9)*Settings!$B$12+MAX(0,MIN(B10,Settings!$B$11)-Settings!$B$10)*Settings!$B$13+MAX(0,B10-Settings!$B$11)*Settings!$B$14,0) -> 84000 | D10: =ROUND(B10*Settings!$B$15,0) -> 24000 | E10: =ROUND(B10*Settings!$B$18,0) -> 1200 | F10: =ROUND((B10-C10-D10-E10)*Settings!$B$20,0) -> 1454 | G10: =B10-C10-D10-E10-F10 -> 289346 | H10: =ROUND(B10*Settings!$B$16,0) -> 24000 | I10: =ROUND(B10*Settings!$B$17,0) -> 8000 | J10: =ROUND(B10*Settings!$B$19,0) -> 1200 | K10: =H10+I10+J10 -> 33200 | L10: =C10+D10+E10+F10+K10 -> 143854
A11: 45839 | B11: 400000 | C11: =ROUND(MAX(0,MIN(B11,Settings!$B$10)-Settings!$B$9)*Settings!$B$12+MAX(0,MIN(B11,Settings!$B$11)-Settings!$B$10)*Settings!$B$13+MAX(0,B11-Settings!$B$11)*Settings!$B$14,0) -> 84000 | D11: =ROUND(B11*Settings!$B$15,0) -> 24000 | E11: =ROUND(B11*Settings!$B$18,0) -> 1200 | F11: =ROUND((B11-C11-D11-E11)*Settings!$B$20,0) -> 1454 | G11: =B11-C11-D11-E11-F11 -> 289346 | H11: =ROUND(B11*Settings!$B$16,0) -> 24000 | I11: =ROUND(B11*Settings!$B$17,0) -> 8000 | J11: =ROUND(B11*Settings!$B$19,0) -> 1200 | K11: =H11+I11+J11 -> 33200 | L11: =C11+D11+E11+F11+K11 -> 143854
A12: 45870 | B12: 400000 | C12: =ROUND(MAX(0,MIN(B12,Settings!$B$10)-Settings!$B$9)*Settings!$B$12+MAX(0,MIN(B12,Settings!$B$11)-Settings!$B$10)*Settings!$B$13+MAX(0,B12-Settings!$B$11)*Settings!$B$14,0) -> 84000 | D12: =ROUND(B12*Settings!$B$15,0) -> 24000 | E12: =ROUND(B12*Settings!$B$18,0) -> 1200 | F12: =ROUND((B12-C12-D12-E12)*Settings!$B$20,0) -> 1454 | G12: =B12-C12-D12-E12-F12 -> 289346 | H12: =ROUND(B12*Settings!$B$16,0) -> 24000 | I12: =ROUND(B12*Settings!$B$17,0) -> 8000 | J12: =ROUND(B12*Settings!$B$19,0) -> 1200 | K12: =H12+I12+J12 -> 33200 | L12: =C12+D12+E12+F12+K12 -> 143854
A13: 45901 | B13: 400000 | C13: =ROUND(MAX(0,MIN(B13,Settings!$B$10)-Settings!$B$9)*Settings!$B$12+MAX(0,MIN(B13,Settings!$B$11)-Settings!$B$10)*Settings!$B$13+MAX(0,B13-Settings!$B$11)*Settings!$B$14,0) -> 84000 | D13: =ROUND(B13*Settings!$B$15,0) -> 24000 | E13: =ROUND(B13*Settings!$B$18,0) -> 1200 | F13: =ROUND((B13-C13-D13-E13)*Settings!$B$20,0) -> 1454 | G13: =B13-C13-D13-E13-F13 -> 289346 | H13: =ROUND(B13*Settings!$B$16,0) -> 24000 | I13: =ROUND(B13*Settings!$B$17,0) -> 8000 | J13: =ROUND(B13*Settings!$B$19,0) -> 1200 | K13: =H13+I13+J13 -> 33200 | L13: =C13+D13+E13+F13+K13 -> 143854
A14: 45931 | B14: 400000 | C14: =ROUND(MAX(0,MIN(B14,Settings!$B$10)-Settings!$B$9)*Settings!$B$12+MAX(0,MIN(B14,Settings!$B$11)-Settings!$B$10)*Settings!$B$13+MAX(0,B14-Settings!$B$11)*Settings!$B$14,0) -> 84000 | D14: =ROUND(B14*Settings!$B$15,0) -> 24000 | E14: =ROUND(B14*Settings!$B$18,0) -> 1200 | F14: =ROUND((B14-C14-D14-E14)*Settings!$B$20,0) -> 1454 | G14: =B14-C14-D14-E14-F14 -> 289346 | H14: =ROUND(B14*Settings!$B$16,0) -> 24000 | I14: =ROUND(B14*Settings!$B$17,0) -> 8000 | J14: =ROUND(B14*Settings!$B$19,0) -> 1200 | K14: =H14+I14+J14 -> 33200 | L14: =C14+D14+E14+F14+K14 -> 143854
A15: 45962 | B15: 400000 | C15: =ROUND(MAX(0,MIN(B15,Settings!$B$10)-Settings!$B$9)*Settings!$B$12+MAX(0,MIN(B15,Settings!$B$11)-Settings!$B$10)*Settings!$B$13+MAX(0,B15-Settings!$B$11)*Settings!$B$14,0) -> 84000 | D15: =ROUND(B15*Settings!$B$15,0) -> 24000 | E15: =ROUND(B15*Settings!$B$18,0) -> 1200 | F15: =ROUND((B15-C15-D15-E15)*Settings!$B$20,0) -> 1454 | G15: =B15-C15-D15-E15-F15 -> 289346 | H15: =ROUND(B15*Settings!$B$16,0) -> 24000 | I15: =ROUND(B15*Settings!$B$17,0) -> 8000 | J15: =ROUND(B15*Settings!$B$19,0) -> 1200 | K15: =H15+I15+J15 -> 33200 | L15: =C15+D15+E15+F15+K15 -> 143854
A16: 45992 | B16: 400000 | C16: =ROUND(MAX(0,MIN(B16,Settings!$B$10)-Settings!$B$9)*Settings!$B$12+MAX(0,MIN(B16,Settings!$B$11)-Settings!$B$10)*Settings!$B$13+MAX(0,B16-Settings!$B$11)*Settings!$B$14,0) -> 84000 | D16: =ROUND(B16*Settings!$B$15,0) -> 24000 | E16: =ROUND(B16*Settings!$B$18,0) -> 1200 | F16: =ROUND((B16-C16-D16-E16)*Settings!$B$20,0) -> 1454 | G16: =B16-C16-D16-E16-F16 -> 289346 | H16: =ROUND(B16*Settings!$B$16,0) -> 24000 | I16: =ROUND(B16*Settings!$B$17,0) -> 8000 | J16: =ROUND(B16*Settings!$B$19,0) -> 1200 | K16: =H16+I16+J16 -> 33200 | L16: =C16+D16+E16+F16+K16 -> 143854
A17: Total | B17: =SUM(B5:B16) -> 4800000 | C17: =SUM(C5:C16) -> 1008000 | D17: =SUM(D5:D16) -> 288000 | E17: =SUM(E5:E16) -> 14400 | F17: =SUM(F5:F16) -> 17448 | G17: =SUM(G5:G16) -> 3472152 | H17: =SUM(H5:H16) -> 288000 | I17: =SUM(I5:I16) -> 96000 | ... L17: =SUM(L5:L16) -> 1726248

Sheet Cash_Book
A1: Cash book (bank account)
A2: Customer receipts are coded 1200 and supplier payments 2100 to clear the control accounts; other lines are coded directly.
A4: Date | B4: Ref | C4: Party | D4: Description | E4: Account code | F4: Receipt | G4: Payment | H4: Account | I4: Running balance
A5: 45660 | B5: PV-001 | C5: Landlord | D5: Payment - rent January | E5: 2100 | F5: 0 | G5: 350000 | H5: =IF(E5="","",IFERROR(INDEX(COA!$B$4:$B$37,MATCH(E5,COA!$A$4:$A$37,0)),"INVALID CODE")) -> Trade payables | I5: =SUMIFS(Opening_TB!$C$5:$C$13,Opening_TB!$A$5:$A$13,Settings!$B$6)+F5-G5 -> 1150000
A6: 45664 | B6: RC-002 | C6: Client B | D6: Receipt - IT support January | E6: 1200 | F6: 550000 | G6: 0 | H6: =IF(E6="","",IFERROR(INDEX(COA!$B$4:$B$37,MATCH(E6,COA!$A$4:$A$37,0)),"INVALID CODE")) -> Trade receivables | I6: =I5+F6-G6 -> 1700000
A7: 45667 | B7: PV-003 | C7: Contractors | D7: Payment - opening balance | E7: 2100 | F7: 0 | G7: 250000 | H7: =IF(E7="","",IFERROR(INDEX(COA!$B$4:$B$37,MATCH(E7,COA!$A$4:$A$37,0)),"INVALID CODE")) -> Trade payables | I7: =I6+F7-G7 -> 1450000
A8: 45672 | B8: RC-004 | C8: Client A | D8: Receipt - opening balance | E8: 1200 | F8: 600000 | G8: 0 | H8: =IF(E8="","",IFERROR(INDEX(COA!$B$4:$B$37,MATCH(E8,COA!$A$4:$A$37,0)),"INVALID CODE")) -> Trade receivables | I8: =I7+F8-G8 -> 2050000
A9: 45672 | B9: PV-005 | C9: Equipment supplier | D9: Purchase of laptops | E9: 1500 | F9: 0 | G9: 950000 | H9: =IF(E9="","",IFERROR(INDEX(COA!$B$4:$B$37,MATCH(E9,COA!$A$4:$A$37,0)),"INVALID CODE")) -> Property, plant and equipment - cost | I9: =I8+F9-G9 -> 1100000
A10: 45677 | B10: RC-006 | C10: Client A | D10: Receipt - milestone 1 | E10: 1200 | F10: 1800000 | G10: 0 | H10: =IF(E10="","",IFERROR(INDEX(COA!$B$4:$B$37,MATCH(E10,COA!$A$4:$A$37,0)),"INVALID CODE")) -> Trade receivables | I10: =I9+F10-G10 -> 2900000
A11: 45681 | B11: PV-007 | C11: Internet provider | D11: Payment - internet January | E11: 2100 | F11: 0 | G11: 60000 | H11: =IF(E11="","",IFERROR(INDEX(COA!$B$4:$B$37,MATCH(E11,COA!$A$4:$A$37,0)),"INVALID CODE")) -> Trade payables | I11: =I10+F11-G11 -> 2840000
A12: 45683 | B12: PV-008 | C12: Utility company | D12: Payment - electricity and water January | E12: 2100 | F12: 0 | G12: 80000 | H12: =IF(E12="","",IFERROR(INDEX(COA!$B$4:$B$37,MATCH(E12,COA!$A$4:$A$37,0)),"INVALID CODE")) -> Trade payables | I12: =I11+F12-G12 -> 2760000
A13: 45685 | B13: PV-009 | C13: Contractors | D13: Payment - contractor services January | E13: 2100 | F13: 0 | G13: 400000 | H13: =IF(E13="","",IFERROR(INDEX(COA!$B$4:$B$37,MATCH(E13,COA!$A$4:$A$37,0)),"INVALID CODE")) -> Trade payables | I13: =I12+F13-G13 -> 2360000
A14: 45685 | B14: PV-010 | C14: Employee | D14: Net salary January | E14: 2410 | F14: 0 | G14: 289346 | H14: =IF(E14="","",IFERROR(INDEX(COA!$B$4:$B$37,MATCH(E14,COA!$A$4:$A$37,0)),"INVALID CODE")) -> Net salaries payable | I14: =I13+F14-G14 -> 2070654
A15: 45691 | B15: PV-011 | C15: Landlord | D15: Payment - rent February | E15: 2100 | F15: 0 | G15: 350000 | H15: =IF(E15="","",IFERROR(INDEX(COA!$B$4:$B$37,MATCH(E15,COA!$A$4:$A$37,0)),"INVALID CODE")) -> Trade payables | I15: =I14+F15-G15 -> 1720654
A16: 45695 | B16: RC-012 | C16: Client B | D16: Receipt - IT support February | E16: 1200 | F16: 550000 | G16: 0 | H16: =IF(E16="","",IFERROR(INDEX(COA!$B$4:$B$37,MATCH(E16,COA!$A$4:$A$37,0)),"INVALID CODE")) -> Trade receivables | I16: =I15+F16-G16 -> 2270654
A17: 45703 | B17: PV-013 | C17: RRA / RSSB | D17: PAYE and RSSB contributions for January | E17: 2400 | F17: 0 | G17: 143854 | H17: =IF(E17="","",IFERROR(INDEX(COA!$B$4:$B$37,MATCH(E17,COA!$A$4:$A$37,0)),"INVALID CODE")) -> PAYE and RSSB contributions payable | I17: =I16+F17-G17 -> 2126800
... A115: 46022 | B115: PV-111 | C115: Bank | D115: Loan interest | E115: 8100 | F115: 0 | G115: 80000 | H115: =IF(E115="","",IFERROR(INDEX(COA!$B$4:$B$37,MATCH(E115,COA!$A$4:$A$37,0)),"INVALID CODE")) -> Interest on bank loan | I115: =I114+F115-G115 -> 1143454
H116: =IF(E116="","",IFERROR(INDEX(COA!$B$4:$B$37,MATCH(E116,COA!$A$4:$A$37,0)),"INVALID CODE"))
H117: =IF(E117="","",IFERROR(INDEX(COA!$B$4:$B$37,MATCH(E117,COA!$A$4:$A$37,0)),"INVALID CODE"))
H118: =IF(E118="","",IFERROR(INDEX(COA!$B$4:$B$37,MATCH(E118,COA!$A$4:$A$37,0)),"INVALID CODE"))
H119: =IF(E119="","",IFERROR(INDEX(COA!$B$4:$B$37,MATCH(E119,COA!$A$4:$A$37,0)),"INVALID CODE"))
H120: =IF(E120="","",IFERROR(INDEX(COA!$B$4:$B$37,MATCH(E120,COA!$A$4:$A$37,0)),"INVALID CODE"))
H121: =IF(E121="","",IFERROR(INDEX(COA!$B$4:$B$37,MATCH(E121,COA!$A$4:$A$37,0)),"INVALID CODE"))
H122: =IF(E122="","",IFERROR(INDEX(COA!$B$4:$B$37,MATCH(E122,COA!$A$4:$A$37,0)),"INVALID CODE"))
H123: =IF(E123="","",IFERROR(INDEX(COA!$B$4:$B$37,MATCH(E123,COA!$A$4:$A$37,0)),"INVALID CODE"))
H124: =IF(E124="","",IFERROR(INDEX(COA!$B$4:$B$37,MATCH(E124,COA!$A$4:$A$37,0)),"INVALID CODE"))
H125: =IF(E125="","",IFERROR(INDEX(COA!$B$4:$B$37,MATCH(E125,COA!$A$4:$A$37,0)),"INVALID CODE"))
H126: =IF(E126="","",IFERROR(INDEX(COA!$B$4:$B$37,MATCH(E126,COA!$A$4:$A$37,0)),"INVALID CODE"))
H127: =IF(E127="","",IFERROR(INDEX(COA!$B$4:$B$37,MATCH(E127,COA!$A$4:$A$37,0)),"INVALID CODE"))
... H155: =IF(E155="","",IFERROR(INDEX(COA!$B$4:$B$37,MATCH(E155,COA!$A$4:$A$37,0)),"INVALID CODE"))

Sheet Fixed_Assets
A1: Fixed asset register and depreciation
A2: Accounting: cost less straight-line depreciation, nil residual value, full month charged in the month of acquisition (Section 17). Tax class drives Rwandan wear and tear.
M3: Forecast depreciation of existing assets (used by the three-statement model)
A4: Asset | B4: Acquired | C4: Cost | D4: Useful life (years) | E4: Tax class | F4: Months used before this year | G4: Accum. depreciation b/f | H4: Months used this year | I4: Depreciation this year | J4: Accum. depreciation c/f | K4: Carrying amount | M4: =Settings!$B$4+1 -> 2026 | N4: =Settings!$B$4+2 -> 2027 | O4: =Settings!$B$4+3 -> 2028
A5: Computers and furniture (2023) | B5: 45170 | C5: 1800000 | D5: 4 | E5: Computers and ICT | F5: =MAX(0,(Settings!$B$4-YEAR(B5))*12-(MONTH(B5)-1)) -> 16 | G5: =MIN(C5,C5/D5*F5/12) -> 600000 | H5: =IF(YEAR(B5)>Settings!$B$4,0,IF(YEAR(B5)<Settings!$B$4,12,12-MONTH(B5)+1)) -> 12 | I5: =ROUND(MIN(C5-G5,C5/D5*H5/12),0) -> 450000 | J5: =G5+I5 -> 1050000 | K5: =C5-J5 -> 750000 | M5: =MIN(C5,C5/D5*(MAX(0,(M$4-YEAR(B5))*12-(MONTH(B5)-1))+12)/12)-MIN(C5,C5/D5*MAX(0,(M$4-YEAR(B5))*12-(MONTH(B5)-1))/12) -> 450000 | N5: =MIN(C5,C5/D5*(MAX(0,(N$4-YEAR(B5))*12-(MONTH(B5)-1))+12)/12)-MIN(C5,C5/D5*MAX(0,(N$4-YEAR(B5))*12-(MONTH(B5)-1))/12) -> 300000 | O5: =MIN(C5,C5/D5*(MAX(0,(O$4-YEAR(B5))*12-(MONTH(B5)-1))+12)/12)-MIN(C5,C5/D5*MAX(0,(O$4-YEAR(B5))*12-(MONTH(B5)-1))/12) -> 0
A6: Laptops | B6: 45672 | C6: 950000 | D6: 3 | E6: Computers and ICT | F6: =MAX(0,(Settings!$B$4-YEAR(B6))*12-(MONTH(B6)-1)) -> 0 | G6: =MIN(C6,C6/D6*F6/12) -> 0 | H6: =IF(YEAR(B6)>Settings!$B$4,0,IF(YEAR(B6)<Settings!$B$4,12,12-MONTH(B6)+1)) -> 12 | I6: =ROUND(MIN(C6-G6,C6/D6*H6/12),0) -> 316667 | J6: =G6+I6 -> 316667 | K6: =C6-J6 -> 633333 | M6: =MIN(C6,C6/D6*(MAX(0,(M$4-YEAR(B6))*12-(MONTH(B6)-1))+12)/12)-MIN(C6,C6/D6*MAX(0,(M$4-YEAR(B6))*12-(MONTH(B6)-1))/12) -> 316666.67 | N6: =MIN(C6,C6/D6*(MAX(0,(N$4-YEAR(B6))*12-(MONTH(B6)-1))+12)/12)-MIN(C6,C6/D6*MAX(0,(N$4-YEAR(B6))*12-(MONTH(B6)-1))/12) -> 316666.67 | O6: =MIN(C6,C6/D6*(MAX(0,(O$4-YEAR(B6))*12-(MONTH(B6)-1))+12)/12)-MIN(C6,C6/D6*MAX(0,(O$4-YEAR(B6))*12-(MONTH(B6)-1))/12) -> 0
A7: Motor vehicle | B7: 45752 | C7: 2000000 | D7: 5 | E7: Other business assets | F7: =MAX(0,(Settings!$B$4-YEAR(B7))*12-(MONTH(B7)-1)) -> 0 | G7: =MIN(C7,C7/D7*F7/12) -> 0 | H7: =IF(YEAR(B7)>Settings!$B$4,0,IF(YEAR(B7)<Settings!$B$4,12,12-MONTH(B7)+1)) -> 9 | I7: =ROUND(MIN(C7-G7,C7/D7*H7/12),0) -> 300000 | J7: =G7+I7 -> 300000 | K7: =C7-J7 -> 1700000 | M7: =MIN(C7,C7/D7*(MAX(0,(M$4-YEAR(B7))*12-(MONTH(B7)-1))+12)/12)-MIN(C7,C7/D7*MAX(0,(M$4-YEAR(B7))*12-(MONTH(B7)-1))/12) -> 400000 | N7: =MIN(C7,C7/D7*(MAX(0,(N$4-YEAR(B7))*12-(MONTH(B7)-1))+12)/12)-MIN(C7,C7/D7*MAX(0,(N$4-YEAR(B7))*12-(MONTH(B7)-1))/12) -> 400000 | O7: =MIN(C7,C7/D7*(MAX(0,(O$4-YEAR(B7))*12-(MONTH(B7)-1))+12)/12)-MIN(C7,C7/D7*MAX(0,(O$4-YEAR(B7))*12-(MONTH(B7)-1))/12) -> 400000
A8: Printer | B8: 45950 | C8: 280000 | D8: 3 | E8: Computers and ICT | F8: =MAX(0,(Settings!$B$4-YEAR(B8))*12-(MONTH(B8)-1)) -> 0 | G8: =MIN(C8,C8/D8*F8/12) -> 0 | H8: =IF(YEAR(B8)>Settings!$B$4,0,IF(YEAR(B8)<Settings!$B$4,12,12-MONTH(B8)+1)) -> 3 | I8: =ROUND(MIN(C8-G8,C8/D8*H8/12),0) -> 23333 | J8: =G8+I8 -> 23333 | K8: =C8-J8 -> 256667 | M8: =MIN(C8,C8/D8*(MAX(0,(M$4-YEAR(B8))*12-(MONTH(B8)-1))+12)/12)-MIN(C8,C8/D8*MAX(0,(M$4-YEAR(B8))*12-(MONTH(B8)-1))/12) -> 93333.333 | N8: =MIN(C8,C8/D8*(MAX(0,(N$4-YEAR(B8))*12-(MONTH(B8)-1))+12)/12)-MIN(C8,C8/D8*MAX(0,(N$4-YEAR(B8))*12-(MONTH(B8)-1))/12) -> 93333.333 | O8: =MIN(C8,C8/D8*(MAX(0,(O$4-YEAR(B8))*12-(MONTH(B8)-1))+12)/12)-MIN(C8,C8/D8*MAX(0,(O$4-YEAR(B8))*12-(MONTH(B8)-1))/12) -> 70000
A9: Total | C9: =SUM(C5:C8) -> 5030000 | G9: =SUM(G5:G8) -> 600000 | I9: =SUM(I5:I8) -> 1090000 | J9: =SUM(J5:J8) -> 1690000 | K9: =SUM(K5:K8) -> 3340000 | M9: =SUM(M5:M8) -> 1260000 | N9: =SUM(N5:N8) -> 1110000 | O9: =SUM(O5:O8) -> 470000

Sheet Loan_Schedule
A1: Bank loan schedule
A2: Term loan for the motor vehicle and working capital: quarterly principal plus interest on the reducing balance.
A3: Amount drawn | B3: 2400000
A4: Drawdown date | B4: 45748
A5: Interest rate (annual, fixed) | B5: 0.16
A6: Quarterly principal repayment | B6: 200000
A7: Security | B7: Charge over the motor vehicle
A9: Quarter | B9: Due date | C9: Year | D9: Opening balance | E9: Interest | F9: Principal | G9: Closing balance | I9: Summary by year
A10: 1 | B10: =EOMONTH($B$4,3*A10-1) -> 45838 | C10: =YEAR(B10) -> 2025 | D10: =$B$3 -> 2400000 | E10: =ROUND(D10*$B$5/4,0) -> 96000 | F10: =MIN(D10,$B$6) -> 200000 | G10: =D10-F10 -> 2200000 | I10: Year | J10: Interest | K10: Principal repaid | L10: Closing balance | M10: Due within 12 months
A11: 2 | B11: =EOMONTH($B$4,3*A11-1) -> 45930 | C11: =YEAR(B11) -> 2025 | D11: =G10 -> 2200000 | E11: =ROUND(D11*$B$5/4,0) -> 88000 | F11: =MIN(D11,$B$6) -> 200000 | G11: =D11-F11 -> 2000000 | I11: =Settings!$B$4+0 -> 2025 | J11: =SUMIFS(Loan_Schedule!$E$10:$E$21,Loan_Schedule!$C$10:$C$21,I11) -> 264000 | K11: =SUMIFS(Loan_Schedule!$F$10:$F$21,Loan_Schedule!$C$10:$C$21,I11) -> 600000 | L11: =$B$3-SUMIFS(Loan_Schedule!$F$10:$F$21,Loan_Schedule!$C$10:$C$21,"<="&I11) -> 1800000 | M11: =MIN(L11,SUMIFS(Loan_Schedule!$F$10:$F$21,Loan_Schedule!$C$10:$C$21,I11+1)) -> 800000
A12: 3 | B12: =EOMONTH($B$4,3*A12-1) -> 46022 | C12: =YEAR(B12) -> 2025 | D12: =G11 -> 2000000 | E12: =ROUND(D12*$B$5/4,0) -> 80000 | F12: =MIN(D12,$B$6) -> 200000 | G12: =D12-F12 -> 1800000 | I12: =Settings!$B$4+1 -> 2026 | J12: =SUMIFS(Loan_Schedule!$E$10:$E$21,Loan_Schedule!$C$10:$C$21,I12) -> 240000 | K12: =SUMIFS(Loan_Schedule!$F$10:$F$21,Loan_Schedule!$C$10:$C$21,I12) -> 800000 | L12: =$B$3-SUMIFS(Loan_Schedule!$F$10:$F$21,Loan_Schedule!$C$10:$C$21,"<="&I12) -> 1000000 | M12: =MIN(L12,SUMIFS(Loan_Schedule!$F$10:$F$21,Loan_Schedule!$C$10:$C$21,I12+1)) -> 800000
A13: 4 | B13: =EOMONTH($B$4,3*A13-1) -> 46112 | C13: =YEAR(B13) -> 2026 | D13: =G12 -> 1800000 | E13: =ROUND(D13*$B$5/4,0) -> 72000 | F13: =MIN(D13,$B$6) -> 200000 | G13: =D13-F13 -> 1600000 | I13: =Settings!$B$4+2 -> 2027 | J13: =SUMIFS(Loan_Schedule!$E$10:$E$21,Loan_Schedule!$C$10:$C$21,I13) -> 112000 | K13: =SUMIFS(Loan_Schedule!$F$10:$F$21,Loan_Schedule!$C$10:$C$21,I13) -> 800000 | L13: =$B$3-SUMIFS(Loan_Schedule!$F$10:$F$21,Loan_Schedule!$C$10:$C$21,"<="&I13) -> 200000 | M13: =MIN(L13,SUMIFS(Loan_Schedule!$F$10:$F$21,Loan_Schedule!$C$10:$C$21,I13+1)) -> 200000
A14: 5 | B14: =EOMONTH($B$4,3*A14-1) -> 46203 | C14: =YEAR(B14) -> 2026 | D14: =G13 -> 1600000 | E14: =ROUND(D14*$B$5/4,0) -> 64000 | F14: =MIN(D14,$B$6) -> 200000 | G14: =D14-F14 -> 1400000 | I14: =Settings!$B$4+3 -> 2028 | J14: =SUMIFS(Loan_Schedule!$E$10:$E$21,Loan_Schedule!$C$10:$C$21,I14) -> 8000 | K14: =SUMIFS(Loan_Schedule!$F$10:$F$21,Loan_Schedule!$C$10:$C$21,I14) -> 200000 | L14: =$B$3-SUMIFS(Loan_Schedule!$F$10:$F$21,Loan_Schedule!$C$10:$C$21,"<="&I14) -> 0 | M14: =MIN(L14,SUMIFS(Loan_Schedule!$F$10:$F$21,Loan_Schedule!$C$10:$C$21,I14+1)) -> 0
A15: 6 | B15: =EOMONTH($B$4,3*A15-1) -> 46295 | C15: =YEAR(B15) -> 2026 | D15: =G14 -> 1400000 | E15: =ROUND(D15*$B$5/4,0) -> 56000 | F15: =MIN(D15,$B$6) -> 200000 | G15: =D15-F15 -> 1200000
A16: 7 | B16: =EOMONTH($B$4,3*A16-1) -> 46387 | C16: =YEAR(B16) -> 2026 | D16: =G15 -> 1200000 | E16: =ROUND(D16*$B$5/4,0) -> 48000 | F16: =MIN(D16,$B$6) -> 200000 | G16: =D16-F16 -> 1000000
A17: 8 | B17: =EOMONTH($B$4,3*A17-1) -> 46477 | C17: =YEAR(B17) -> 2027 | D17: =G16 -> 1000000 | E17: =ROUND(D17*$B$5/4,0) -> 40000 | F17: =MIN(D17,$B$6) -> 200000 | G17: =D17-F17 -> 800000
A18: 9 | B18: =EOMONTH($B$4,3*A18-1) -> 46568 | C18: =YEAR(B18) -> 2027 | D18: =G17 -> 800000 | E18: =ROUND(D18*$B$5/4,0) -> 32000 | F18: =MIN(D18,$B$6) -> 200000 | G18: =D18-F18 -> 600000
A19: 10 | B19: =EOMONTH($B$4,3*A19-1) -> 46660 | C19: =YEAR(B19) -> 2027 | D19: =G18 -> 600000 | E19: =ROUND(D19*$B$5/4,0) -> 24000 | F19: =MIN(D19,$B$6) -> 200000 | G19: =D19-F19 -> 400000
A20: 11 | B20: =EOMONTH($B$4,3*A20-1) -> 46752 | C20: =YEAR(B20) -> 2027 | D20: =G19 -> 400000 | E20: =ROUND(D20*$B$5/4,0) -> 16000 | F20: =MIN(D20,$B$6) -> 200000 | G20: =D20-F20 -> 200000
A21: 12 | B21: =EOMONTH($B$4,3*A21-1) -> 46843 | C21: =YEAR(B21) -> 2028 | D21: =G20 -> 200000 | E21: =ROUND(D21*$B$5/4,0) -> 8000 | F21: =MIN(D21,$B$6) -> 200000 | G21: =D21-F21 -> 0

Sheet Tax_Computation
A1: Corporate income tax computation and deferred tax (Rwanda)
A2: Accounting depreciation is added back and replaced by wear and tear allowances on reducing-balance pools; a full allowance is taken in the year an asset is acquired (assumption).
A4: Wear and tear pools
A5: Pool | B5: Rate | C5: Opening tax value | D5: Additions | E5: Allowance | F5: Closing tax value
A6: Computers and ICT | B6: =Settings!$B$22 -> 0.5 | C6: 900000 | D6: =SUMPRODUCT((YEAR(Fixed_Assets!$B$5:$B$8)=Settings!$B$4)*(Fixed_Assets!$E$5:$E$8=A6)*Fixed_Assets!$C$5:$C$8) -> 1230000 | E6: =ROUND(B6*(C6+D6),0) -> 1065000 | F6: =C6+D6-E6 -> 1065000
A7: Other business assets | B7: =Settings!$B$23 -> 0.25 | C7: 0 | D7: =SUMPRODUCT((YEAR(Fixed_Assets!$B$5:$B$8)=Settings!$B$4)*(Fixed_Assets!$E$5:$E$8=A7)*Fixed_Assets!$C$5:$C$8) -> 2000000 | E7: =ROUND(B7*(C7+D7),0) -> 500000 | F7: =C7+D7-E7 -> 1500000
A8: Total | C8: =SUM(C6:C7) -> 900000 | D8: =SUM(D6:D7) -> 3230000 | E8: =SUM(E6:E7) -> 1565000 | F8: =SUM(F6:F7) -> 2565000
A10: Taxable income
A11: Profit before tax | B11: =SoCI!C17 -> 1119600
A12: Add: accounting depreciation | B12: =Fixed_Assets!I9 -> 1090000
A13: Add: non-deductible expenses (fines, penalties, private costs) | B13: 0
A14: Less: wear and tear allowances | B14: =-E8 -> -1565000
A15: Taxable income | B15: =SUM(B11:B14) -> 644600
A16: Current income tax at the corporate rate | B16: =ROUND(MAX(0,B15)*Settings!$B$5,0) -> 180488
A18: Deferred tax (temporary differences on PPE)
A19: Carrying amount of property, plant and equipment | B19: =Fixed_Assets!K9 -> 3340000
A20: Tax base (closing tax values) | B20: =F8 -> 2565000
A21: Taxable temporary difference | B21: =B19-B20 -> 775000
A22: Deferred tax liability at year end | B22: =ROUND(B21*Settings!$B$5,0) -> 217000
A23: Deferred tax liability at start of year | B23: =-SUMIFS(Opening_TB!$C$5:$C$13,Opening_TB!$A$5:$A$13,2700) -> 84000
A24: Deferred tax charge / (credit) for the year | B24: =B22-B23 -> 133000
A26: Current tax account
A27: Payable at start of year | B27: =-SUMIFS(Opening_TB!$C$5:$C$13,Opening_TB!$A$5:$A$13,2300) -> 180000
A28: Current tax for the year | B28: =B16 -> 180488
A29: Paid: prior-year balance and quarterly prepayments | B29: =-SUMIFS(Cash_Book!$G$5:$G$155,Cash_Book!$E$5:$E$155,2300) -> -315000
A30: Payable / (recoverable) at year end | B30: =SUM(B27:B29) -> 45488

Sheet Journals
A1: General journal — period-end entries
A2: Every entry balances. Amounts in green are linked to the supporting sheet.
A4: Date | B4: Ref | C4: Description | D4: Account code | E4: Debit | F4: Credit | G4: Account
A5: =DATE(Settings!$B$4,12,31) -> 46022 | B5: JV-01 | C5: Depreciation for the year | D5: 6100 | E5: =Fixed_Assets!I9 -> 1090000 | G5: =IF(D5="","",IFERROR(INDEX(COA!$B$4:$B$37,MATCH(D5,COA!$A$4:$A$37,0)),"INVALID CODE")) -> Depreciation
A6: =DATE(Settings!$B$4,12,31) -> 46022 | B6: JV-01 | C6: Depreciation for the year | D6: 1510 | F6: =Fixed_Assets!I9 -> 1090000 | G6: =IF(D6="","",IFERROR(INDEX(COA!$B$4:$B$37,MATCH(D6,COA!$A$4:$A$37,0)),"INVALID CODE")) -> Property, plant and equipment - accumulated depreciation
A7: =DATE(Settings!$B$4,12,31) -> 46022 | B7: JV-02 | C7: Accrue December electricity and water (bill not yet received) | D7: 5300 | E7: 85000 | G7: =IF(D7="","",IFERROR(INDEX(COA!$B$4:$B$37,MATCH(D7,COA!$A$4:$A$37,0)),"INVALID CODE")) -> Electricity and water
A8: =DATE(Settings!$B$4,12,31) -> 46022 | B8: JV-02 | C8: Accrue December electricity and water (bill not yet received) | D8: 2200 | F8: 85000 | G8: =IF(D8="","",IFERROR(INDEX(COA!$B$4:$B$37,MATCH(D8,COA!$A$4:$A$37,0)),"INVALID CODE")) -> Accrued expenses
A9: =DATE(Settings!$B$4,12,31) -> 46022 | B9: JV-03 | C9: Payroll for the year - gross salaries | D9: 5010 | E9: =Payroll!B17 -> 4800000 | G9: =IF(D9="","",IFERROR(INDEX(COA!$B$4:$B$37,MATCH(D9,COA!$A$4:$A$37,0)),"INVALID CODE")) -> Salaries and wages
A10: =DATE(Settings!$B$4,12,31) -> 46022 | B10: JV-03 | C10: Payroll for the year - employer RSSB contributions | D10: 5020 | E10: =Payroll!K17 -> 398400 | G10: =IF(D10="","",IFERROR(INDEX(COA!$B$4:$B$37,MATCH(D10,COA!$A$4:$A$37,0)),"INVALID CODE")) -> Employer RSSB contributions
A11: =DATE(Settings!$B$4,12,31) -> 46022 | B11: JV-03 | C11: Payroll for the year - net pay due to employee | D11: 2410 | F11: =Payroll!G17 -> 3472152 | G11: =IF(D11="","",IFERROR(INDEX(COA!$B$4:$B$37,MATCH(D11,COA!$A$4:$A$37,0)),"INVALID CODE")) -> Net salaries payable
A12: =DATE(Settings!$B$4,12,31) -> 46022 | B12: JV-03 | C12: Payroll for the year - PAYE and RSSB due | D12: 2400 | F12: =Payroll!L17 -> 1726248 | G12: =IF(D12="","",IFERROR(INDEX(COA!$B$4:$B$37,MATCH(D12,COA!$A$4:$A$37,0)),"INVALID CODE")) -> PAYE and RSSB contributions payable
A13: =DATE(Settings!$B$4,12,31) -> 46022 | B13: JV-04 | C13: Current income tax for the year | D13: 7000 | E13: =Tax_Computation!B16 -> 180488 | G13: =IF(D13="","",IFERROR(INDEX(COA!$B$4:$B$37,MATCH(D13,COA!$A$4:$A$37,0)),"INVALID CODE")) -> Current income tax
A14: =DATE(Settings!$B$4,12,31) -> 46022 | B14: JV-04 | C14: Current income tax for the year | D14: 2300 | F14: =Tax_Computation!B16 -> 180488 | G14: =IF(D14="","",IFERROR(INDEX(COA!$B$4:$B$37,MATCH(D14,COA!$A$4:$A$37,0)),"INVALID CODE")) -> Income tax payable
A15: =DATE(Settings!$B$4,12,31) -> 46022 | B15: JV-05 | C15: Deferred tax charge for the year | D15: 7100 | E15: =Tax_Computation!B24 -> 133000 | G15: =IF(D15="","",IFERROR(INDEX(COA!$B$4:$B$37,MATCH(D15,COA!$A$4:$A$37,0)),"INVALID CODE")) -> Deferred tax
A16: =DATE(Settings!$B$4,12,31) -> 46022 | B16: JV-05 | C16: Deferred tax charge for the year | D16: 2700 | F16: =Tax_Computation!B24 -> 133000 | G16: =IF(D16="","",IFERROR(INDEX(COA!$B$4:$B$37,MATCH(D16,COA!$A$4:$A$37,0)),"INVALID CODE")) -> Deferred tax liability
G17: =IF(D17="","",IFERROR(INDEX(COA!$B$4:$B$37,MATCH(D17,COA!$A$4:$A$37,0)),"INVALID CODE"))
G18: =IF(D18="","",IFERROR(INDEX(COA!$B$4:$B$37,MATCH(D18,COA!$A$4:$A$37,0)),"INVALID CODE"))
G19: =IF(D19="","",IFERROR(INDEX(COA!$B$4:$B$37,MATCH(D19,COA!$A$4:$A$37,0)),"INVALID CODE"))
G20: =IF(D20="","",IFERROR(INDEX(COA!$B$4:$B$37,MATCH(D20,COA!$A$4:$A$37,0)),"INVALID CODE"))
G21: =IF(D21="","",IFERROR(INDEX(COA!$B$4:$B$37,MATCH(D21,COA!$A$4:$A$37,0)),"INVALID CODE"))
G22: =IF(D22="","",IFERROR(INDEX(COA!$B$4:$B$37,MATCH(D22,COA!$A$4:$A$37,0)),"INVALID CODE"))
G23: =IF(D23="","",IFERROR(INDEX(COA!$B$4:$B$37,MATCH(D23,COA!$A$4:$A$37,0)),"INVALID CODE"))
G24: =IF(D24="","",IFERROR(INDEX(COA!$B$4:$B$37,MATCH(D24,COA!$A$4:$A$37,0)),"INVALID CODE"))
G25: =IF(D25="","",IFERROR(INDEX(COA!$B$4:$B$37,MATCH(D25,COA!$A$4:$A$37,0)),"INVALID CODE"))
G26: =IF(D26="","",IFERROR(INDEX(COA!$B$4:$B$37,MATCH(D26,COA!$A$4:$A$37,0)),"INVALID CODE"))
G27: =IF(D27="","",IFERROR(INDEX(COA!$B$4:$B$37,MATCH(D27,COA!$A$4:$A$37,0)),"INVALID CODE"))
G28: =IF(D28="","",IFERROR(INDEX(COA!$B$4:$B$37,MATCH(D28,COA!$A$4:$A$37,0)),"INVALID CODE"))
... G56: =IF(D56="","",IFERROR(INDEX(COA!$B$4:$B$37,MATCH(D56,COA!$A$4:$A$37,0)),"INVALID CODE"))
D58: Totals | E58: =SUM(Journals!$E$5:$E$56) -> 6686888 | F58: =SUM(Journals!$F$5:$F$56) -> 6686888

Sheet Trial_Balance
A1: ="Trial balance at 31 December "&Settings!$B$4 -> Trial balance at 31 December 2025
A2: Built entirely by formula: opening + debits − credits from the registers, payroll, cash book and journals. Debit balances positive.
A4: Code | B4: Account | C4: Class | D4: Statement line | E4: Opening | F4: Debits | G4: Credits | H4: Closing | I4: Closing Dr | J4: Closing Cr
A5: =COA!A4 -> 1100 | B5: =COA!B4 -> Bank | C5: =COA!C4 -> Asset | D5: =COA!D4 -> Cash and cash equivalents | E5: =SUMIFS(Opening_TB!$C$5:$C$13,Opening_TB!$A$5:$A$13,A5) -> 1500000 | F5: =SUMIFS(Purchase_Register!$F$5:$F$94,Purchase_Register!$E$5:$E$94,A5)+(A5=Settings!$B$7)*SUM(Sales_Register!$F$5:$F$65)+SUMIFS(Cash_Book!$G$5:$G$155,Cash_Book!$E$5:$E$155,A5)+(A5=Settings!$B$6)*SUM(Cash_Book!$F$5:$F$155)+SUMIFS(Journals!$E$5:$E$56,Journals!$D$5:$D$56,A5) -> 21400000 | G5: =SUMIFS(Sales_Register!$F$5:$F$65,Sales_Register!$E$5:$E$65,A5)+(A5=Settings!$B$8)*SUM(Purchase_Register!$F$5:$F$94)+SUMIFS(Cash_Book!$F$5:$F$155,Cash_Book!$E$5:$E$155,A5)+(A5=Settings!$B$6)*SUM(Cash_Book!$G$5:$G$155)+SUMIFS(Journals!$F$5:$F$56,Journals!$D$5:$D$56,A5) -> 21756546 | H5: =E5+F5-G5 -> 1143454 | I5: =MAX(0,H5) -> 1143454 | J5: =MAX(0,-H5) -> 0
A6: =COA!A5 -> 1200 | B6: =COA!B5 -> Trade receivables | C6: =COA!C5 -> Asset | D6: =COA!D5 -> Trade and other receivables | E6: =SUMIFS(Opening_TB!$C$5:$C$13,Opening_TB!$A$5:$A$13,A6) -> 600000 | F6: =SUMIFS(Purchase_Register!$F$5:$F$94,Purchase_Register!$E$5:$E$94,A6)+(A6=Settings!$B$7)*SUM(Sales_Register!$F$5:$F$65)+SUMIFS(Cash_Book!$G$5:$G$155,Cash_Book!$E$5:$E$155,A6)+(A6=Settings!$B$6)*SUM(Cash_Book!$F$5:$F$155)+SUMIFS(Journals!$E$5:$E$56,Journals!$D$5:$D$56,A6) -> 19550000 | G6: =SUMIFS(Sales_Register!$F$5:$F$65,Sales_Register!$E$5:$E$65,A6)+(A6=Settings!$B$8)*SUM(Purchase_Register!$F$5:$F$94)+SUMIFS(Cash_Book!$F$5:$F$155,Cash_Book!$E$5:$E$155,A6)+(A6=Settings!$B$6)*SUM(Cash_Book!$G$5:$G$155)+SUMIFS(Journals!$F$5:$F$56,Journals!$D$5:$D$56,A6) -> 19000000 | H6: =E6+F6-G6 -> 1150000 | I6: =MAX(0,H6) -> 1150000 | J6: =MAX(0,-H6) -> 0
A7: =COA!A6 -> 1300 | B7: =COA!B6 -> Prepayments | C7: =COA!C6 -> Asset | D7: =COA!D6 -> Prepayments | E7: =SUMIFS(Opening_TB!$C$5:$C$13,Opening_TB!$A$5:$A$13,A7) -> 0 | F7: =SUMIFS(Purchase_Register!$F$5:$F$94,Purchase_Register!$E$5:$E$94,A7)+(A7=Settings!$B$7)*SUM(Sales_Register!$F$5:$F$65)+SUMIFS(Cash_Book!$G$5:$G$155,Cash_Book!$E$5:$E$155,A7)+(A7=Settings!$B$6)*SUM(Cash_Book!$F$5:$F$155)+SUMIFS(Journals!$E$5:$E$56,Journals!$D$5:$D$56,A7) -> 350000 | G7: =SUMIFS(Sales_Register!$F$5:$F$65,Sales_Register!$E$5:$E$65,A7)+(A7=Settings!$B$8)*SUM(Purchase_Register!$F$5:$F$94)+SUMIFS(Cash_Book!$F$5:$F$155,Cash_Book!$E$5:$E$155,A7)+(A7=Settings!$B$6)*SUM(Cash_Book!$G$5:$G$155)+SUMIFS(Journals!$F$5:$F$56,Journals!$D$5:$D$56,A7) -> 0 | H7: =E7+F7-G7 -> 350000 | I7: =MAX(0,H7) -> 350000 | J7: =MAX(0,-H7) -> 0
A8: =COA!A7 -> 1500 | B8: =COA!B7 -> Property, plant and equipment - cost | C8: =COA!C7 -> Asset | D8: =COA!D7 -> Property, plant and equipment | E8: =SUMIFS(Opening_TB!$C$5:$C$13,Opening_TB!$A$5:$A$13,A8) -> 1800000 | F8: =SUMIFS(Purchase_Register!$F$5:$F$94,Purchase_Register!$E$5:$E$94,A8)+(A8=Settings!$B$7)*SUM(Sales_Register!$F$5:$F$65)+SUMIFS(Cash_Book!$G$5:$G$155,Cash_Book!$E$5:$E$155,A8)+(A8=Settings!$B$6)*SUM(Cash_Book!$F$5:$F$155)+SUMIFS(Journals!$E$5:$E$56,Journals!$D$5:$D$56,A8) -> 3230000 | G8: =SUMIFS(Sales_Register!$F$5:$F$65,Sales_Register!$E$5:$E$65,A8)+(A8=Settings!$B$8)*SUM(Purchase_Register!$F$5:$F$94)+SUMIFS(Cash_Book!$F$5:$F$155,Cash_Book!$E$5:$E$155,A8)+(A8=Settings!$B$6)*SUM(Cash_Book!$G$5:$G$155)+SUMIFS(Journals!$F$5:$F$56,Journals!$D$5:$D$56,A8) -> 0 | H8: =E8+F8-G8 -> 5030000 | I8: =MAX(0,H8) -> 5030000 | J8: =MAX(0,-H8) -> 0
A9: =COA!A8 -> 1510 | B9: =COA!B8 -> Property, plant and equipment - accumulated depreciation | C9: =COA!C8 -> Asset | D9: =COA!D8 -> Property, plant and equipment | E9: =SUMIFS(Opening_TB!$C$5:$C$13,Opening_TB!$A$5:$A$13,A9) -> -600000 | F9: =SUMIFS(Purchase_Register!$F$5:$F$94,Purchase_Register!$E$5:$E$94,A9)+(A9=Settings!$B$7)*SUM(Sales_Register!$F$5:$F$65)+SUMIFS(Cash_Book!$G$5:$G$155,Cash_Book!$E$5:$E$155,A9)+(A9=Settings!$B$6)*SUM(Cash_Book!$F$5:$F$155)+SUMIFS(Journals!$E$5:$E$56,Journals!$D$5:$D$56,A9) -> 0 | G9: =SUMIFS(Sales_Register!$F$5:$F$65,Sales_Register!$E$5:$E$65,A9)+(A9=Settings!$B$8)*SUM(Purchase_Register!$F$5:$F$94)+SUMIFS(Cash_Book!$F$5:$F$155,Cash_Book!$E$5:$E$155,A9)+(A9=Settings!$B$6)*SUM(Cash_Book!$G$5:$G$155)+SUMIFS(Journals!$F$5:$F$56,Journals!$D$5:$D$56,A9) -> 1090000 | H9: =E9+F9-G9 -> -1690000 | I9: =MAX(0,H9) -> 0 | J9: =MAX(0,-H9) -> 1690000
A10: =COA!A9 -> 2100 | B10: =COA!B9 -> Trade payables | C10: =COA!C9 -> Liability | D10: =COA!D9 -> Trade and other payables | E10: =SUMIFS(Opening_TB!$C$5:$C$13,Opening_TB!$A$5:$A$13,A10) -> -250000 | F10: =SUMIFS(Purchase_Register!$F$5:$F$94,Purchase_Register!$E$5:$E$94,A10)+(A10=Settings!$B$7)*SUM(Sales_Register!$F$5:$F$65)+SUMIFS(Cash_Book!$G$5:$G$155,Cash_Book!$E$5:$E$155,A10)+(A10=Settings!$B$6)*SUM(Cash_Book!$F$5:$F$155)+SUMIFS(Journals!$E$5:$E$56,Journals!$D$5:$D$56,A10) -> 11315000 | G10: =SUMIFS(Sales_Register!$F$5:$F$65,Sales_Register!$E$5:$E$65,A10)+(A10=Settings!$B$8)*SUM(Purchase_Register!$F$5:$F$94)+SUMIFS(Cash_Book!$F$5:$F$155,Cash_Book!$E$5:$E$155,A10)+(A10=Settings!$B$6)*SUM(Cash_Book!$G$5:$G$155)+SUMIFS(Journals!$F$5:$F$56,Journals!$D$5:$D$56,A10) -> 11565000 | H10: =E10+F10-G10 -> -500000 | I10: =MAX(0,H10) -> 0 | J10: =MAX(0,-H10) -> 500000
A11: =COA!A10 -> 2200 | B11: =COA!B10 -> Accrued expenses | C11: =COA!C10 -> Liability | D11: =COA!D10 -> Trade and other payables | E11: =SUMIFS(Opening_TB!$C$5:$C$13,Opening_TB!$A$5:$A$13,A11) -> 0 | F11: =SUMIFS(Purchase_Register!$F$5:$F$94,Purchase_Register!$E$5:$E$94,A11)+(A11=Settings!$B$7)*SUM(Sales_Register!$F$5:$F$65)+SUMIFS(Cash_Book!$G$5:$G$155,Cash_Book!$E$5:$E$155,A11)+(A11=Settings!$B$6)*SUM(Cash_Book!$F$5:$F$155)+SUMIFS(Journals!$E$5:$E$56,Journals!$D$5:$D$56,A11) -> 0 | G11: =SUMIFS(Sales_Register!$F$5:$F$65,Sales_Register!$E$5:$E$65,A11)+(A11=Settings!$B$8)*SUM(Purchase_Register!$F$5:$F$94)+SUMIFS(Cash_Book!$F$5:$F$155,Cash_Book!$E$5:$E$155,A11)+(A11=Settings!$B$6)*SUM(Cash_Book!$G$5:$G$155)+SUMIFS(Journals!$F$5:$F$56,Journals!$D$5:$D$56,A11) -> 85000 | H11: =E11+F11-G11 -> -85000 | I11: =MAX(0,H11) -> 0 | J11: =MAX(0,-H11) -> 85000
A12: =COA!A11 -> 2300 | B12: =COA!B11 -> Income tax payable | C12: =COA!C11 -> Liability | D12: =COA!D11 -> Current income tax liability | E12: =SUMIFS(Opening_TB!$C$5:$C$13,Opening_TB!$A$5:$A$13,A12) -> -180000 | F12: =SUMIFS(Purchase_Register!$F$5:$F$94,Purchase_Register!$E$5:$E$94,A12)+(A12=Settings!$B$7)*SUM(Sales_Register!$F$5:$F$65)+SUMIFS(Cash_Book!$G$5:$G$155,Cash_Book!$E$5:$E$155,A12)+(A12=Settings!$B$6)*SUM(Cash_Book!$F$5:$F$155)+SUMIFS(Journals!$E$5:$E$56,Journals!$D$5:$D$56,A12) -> 315000 | G12: =SUMIFS(Sales_Register!$F$5:$F$65,Sales_Register!$E$5:$E$65,A12)+(A12=Settings!$B$8)*SUM(Purchase_Register!$F$5:$F$94)+SUMIFS(Cash_Book!$F$5:$F$155,Cash_Book!$E$5:$E$155,A12)+(A12=Settings!$B$6)*SUM(Cash_Book!$G$5:$G$155)+SUMIFS(Journals!$F$5:$F$56,Journals!$D$5:$D$56,A12) -> 180488 | H12: =E12+F12-G12 -> -45488 | I12: =MAX(0,H12) -> 0 | J12: =MAX(0,-H12) -> 45488
A13: =COA!A12 -> 2400 | B13: =COA!B12 -> PAYE and RSSB contributions payable | C13: =COA!C12 -> Liability | D13: =COA!D12 -> PAYE and social security payable | E13: =SUMIFS(Opening_TB!$C$5:$C$13,Opening_TB!$A$5:$A$13,A13) -> 0 | F13: =SUMIFS(Purchase_Register!$F$5:$F$94,Purchase_Register!$E$5:$E$94,A13)+(A13=Settings!$B$7)*SUM(Sales_Register!$F$5:$F$65)+SUMIFS(Cash_Book!$G$5:$G$155,Cash_Book!$E$5:$E$155,A13)+(A13=Settings!$B$6)*SUM(Cash_Book!$F$5:$F$155)+SUMIFS(Journals!$E$5:$E$56,Journals!$D$5:$D$56,A13) -> 1582394 | G13: =SUMIFS(Sales_Register!$F$5:$F$65,Sales_Register!$E$5:$E$65,A13)+(A13=Settings!$B$8)*SUM(Purchase_Register!$F$5:$F$94)+SUMIFS(Cash_Book!$F$5:$F$155,Cash_Book!$E$5:$E$155,A13)+(A13=Settings!$B$6)*SUM(Cash_Book!$G$5:$G$155)+SUMIFS(Journals!$F$5:$F$56,Journals!$D$5:$D$56,A13) -> 1726248 | H13: =E13+F13-G13 -> -143854 | I13: =MAX(0,H13) -> 0 | J13: =MAX(0,-H13) -> 143854
A14: =COA!A13 -> 2410 | B14: =COA!B13 -> Net salaries payable | C14: =COA!C13 -> Liability | D14: =COA!D13 -> Trade and other payables | E14: =SUMIFS(Opening_TB!$C$5:$C$13,Opening_TB!$A$5:$A$13,A14) -> 0 | F14: =SUMIFS(Purchase_Register!$F$5:$F$94,Purchase_Register!$E$5:$E$94,A14)+(A14=Settings!$B$7)*SUM(Sales_Register!$F$5:$F$65)+SUMIFS(Cash_Book!$G$5:$G$155,Cash_Book!$E$5:$E$155,A14)+(A14=Settings!$B$6)*SUM(Cash_Book!$F$5:$F$155)+SUMIFS(Journals!$E$5:$E$56,Journals!$D$5:$D$56,A14) -> 3472152 | G14: =SUMIFS(Sales_Register!$F$5:$F$65,Sales_Register!$E$5:$E$65,A14)+(A14=Settings!$B$8)*SUM(Purchase_Register!$F$5:$F$94)+SUMIFS(Cash_Book!$F$5:$F$155,Cash_Book!$E$5:$E$155,A14)+(A14=Settings!$B$6)*SUM(Cash_Book!$G$5:$G$155)+SUMIFS(Journals!$F$5:$F$56,Journals!$D$5:$D$56,A14) -> 3472152 | H14: =E14+F14-G14 -> 0 | I14: =MAX(0,H14) -> 0 | J14: =MAX(0,-H14) -> 0
A15: =COA!A14 -> 2500 | B15: =COA!B14 -> Bank loan | C15: =COA!C14 -> Liability | D15: =COA!D14 -> Borrowings | E15: =SUMIFS(Opening_TB!$C$5:$C$13,Opening_TB!$A$5:$A$13,A15) -> 0 | F15: =SUMIFS(Purchase_Register!$F$5:$F$94,Purchase_Register!$E$5:$E$94,A15)+(A15=Settings!$B$7)*SUM(Sales_Register!$F$5:$F$65)+SUMIFS(Cash_Book!$G$5:$G$155,Cash_Book!$E$5:$E$155,A15)+(A15=Settings!$B$6)*SUM(Cash_Book!$F$5:$F$155)+SUMIFS(Journals!$E$5:$E$56,Journals!$D$5:$D$56,A15) -> 600000 | G15: =SUMIFS(Sales_Register!$F$5:$F$65,Sales_Register!$E$5:$E$65,A15)+(A15=Settings!$B$8)*SUM(Purchase_Register!$F$5:$F$94)+SUMIFS(Cash_Book!$F$5:$F$155,Cash_Book!$E$5:$E$155,A15)+(A15=Settings!$B$6)*SUM(Cash_Book!$G$5:$G$155)+SUMIFS(Journals!$F$5:$F$56,Journals!$D$5:$D$56,A15) -> 2400000 | H15: =E15+F15-G15 -> -1800000 | I15: =MAX(0,H15) -> 0 | J15: =MAX(0,-H15) -> 1800000
